Traceback (most recent call last):
  File "C:\Users\Mark\AppData\Roaming\Python\Python310\site-packages\jupyter_cache\executors\utils.py", line 58, in single_nb_execution
    executenb(
  File "C:\Users\Mark\AppData\Roaming\Python\Python310\site-packages\nbclient\client.py", line 1314, in execute
    return NotebookClient(nb=nb, resources=resources, km=km, **kwargs).execute()
  File "C:\Users\Mark\AppData\Roaming\Python\Python310\site-packages\jupyter_core\utils\__init__.py", line 173, in wrapped
    return loop.run_until_complete(inner)
  File "C:\Program Files\Python310\lib\asyncio\base_events.py", line 646, in run_until_complete
    return future.result()
  File "C:\Users\Mark\AppData\Roaming\Python\Python310\site-packages\nbclient\client.py", line 709, in async_execute
    await self.async_execute_cell(
  File "C:\Users\Mark\AppData\Roaming\Python\Python310\site-packages\nbclient\client.py", line 1062, in async_execute_cell
    await self._check_raise_for_error(cell, cell_index, exec_reply)
  File "C:\Users\Mark\AppData\Roaming\Python\Python310\site-packages\nbclient\client.py", line 918, in _check_raise_for_error
    raise CellExecutionError.from_cell_and_msg(cell, exec_reply_content)
nbclient.exceptions.CellExecutionError: An error occurred while executing the following cell:
------------------
from IPython.display import Image

fig.write_image("minta.png")
Image(filename="minta.png")
------------------


[1;31m---------------------------------------------------------------------------[0m
[1;31mAttributeError[0m                            Traceback (most recent call last)
Cell [1;32mIn[6], line 3[0m
[0;32m      1[0m [38;5;28;01mfrom[39;00m [38;5;21;01mIPython[39;00m[38;5;21;01m.[39;00m[38;5;21;01mdisplay[39;00m [38;5;28;01mimport[39;00m Image
[1;32m----> 3[0m [43mfig[49m[38;5;241;43m.[39;49m[43mwrite_image[49m([38;5;124m"[39m[38;5;124mminta.png[39m[38;5;124m"[39m)
[0;32m      4[0m Image(filename[38;5;241m=[39m[38;5;124m"[39m[38;5;124mminta.png[39m[38;5;124m"[39m)

[1;31mAttributeError[0m: 'Figure' object has no attribute 'write_image'

